<?xml version='1.0'?>

<robot name="diff_robot" xmlns:xacro="http://www.ros.org/wiki/xacro">

<xacro:macro name="wheel" params="side mass x:=0 y:=0 z:=0 radius length">

    <!-- Right wheel is on the negative y axis -->
    <xacro:property name="reflect" value="-1"/>
    <xacro:if value="${side.endswith('left')}">
        <xacro:property name="reflect" value="1"/>
    </xacro:if>

    <link name="${side}_wheel">
        
        <visual name="${side}_wheel_visual">
            <origin xyz="0 0 0" rpy="${pi/2} 0 0"/>
            <geometry>
                <cylinder radius="${radius}" length="${length}"/>
            </geometry>
            <!-- Color For Rviz-->
            <material name="black"/>
        </visual>

        <collision name="${side}_wheel_collision">
            <origin xyz="0 0 0" rpy="${pi/2} 0 0"/>
            <geometry>
                <cylinder radius="${radius}" length="${length}"/>
            </geometry>
        </collision>

        <inertial>
            <origin xyz="0 0 0" rpy="${pi/2} 0 0"/>
            <mass value="${mass}"/>
            <xacro:cylinder_inertia m="${mass}" r="${radius}" h="${length}"/>
        </inertial>

    </link>

    <joint name="${side}_wheel_joint" type="continuous">
        <origin xyz="${x} ${reflect*y} ${z}" rpy="0.0 0.0 0.0"/>
        <parent link="chassis"/>
        <child link="${side}_wheel"/>
        <axis xyz="0.0 1 0.0"/>
    </joint>

</xacro:macro>

</robot>