<?xml version='1.0'?>

<robot name="my_robot" xmlns:xacro="http://www.ros.org/wiki/xacro">

<xacro:macro name="wheel" params="side mass x:=0 y:=0 z:=0 radius length">

    <xacro:property name="reflect" value="1"/>
    <xacro:if value="${side.endswith('left')}">
        <xacro:property name="reflect" value="-1"/>
    </xacro:if>

    <link name="${side}_wheel">

        <inertial>
            <origin xyz="0.0 0.0 0.0" rpy="0.0 1.5707 1.5707"/>
            <mass value="${mass}"/>
            <inertia 
                ixx="${(mass/12)*(3*radius*radius+length*length)}" ixy="0.0" ixz="0.0" 
                iyy="${(mass/12)*(3*radius*radius+length*length)}" iyz="0.0" 
                izz="${(mass/2)*(radius*radius)}"
            />
        </inertial>
        
        <visual name="${side}_wheel_visual">
            <origin xyz="0.0 0 0" rpy="0.0 1.5707 1.5707"/>
            <geometry>
                <cylinder radius="${radius}" length="${length}"/>
            </geometry>
        </visual>

        <collision name="${side}_wheel_collision">
            <origin xyz="0.0 0 0" rpy="0.0 1.5707 1.5707"/>
            <geometry>
                <cylinder radius="${radius}" length="${length}"/>
            </geometry>
        </collision>

    </link>

    <joint name="${side}_wheel_hinge" type="continuous">
        <origin xyz="${x} ${reflect*y} ${z}" rpy="0.0 0.0 0.0"/>
        <parent link="chassis"/>
        <child link="${side}_wheel"/>
        <axis xyz="0.0 1 0.0"/>
    </joint>

    <gazebo reference="${side}_wheel">
        <material>Gazebo/Black </material>
    </gazebo>

</xacro:macro>

</robot>